Workbook

Sheet PCP
A1: PUT-CALL PARITY (PCP)
A3: 1) DATA COLLECTED
B4: Variable | C4: XEO (European) | D4: OEX (American)
B5: Index level (S) | C5: 3302.46 | D5: 3303.02
B6: Risk-free rate (r) | C6: 0.0371 | D6: 0.0371
B7: Time to maturity (T) (42/365 days) | C7: 0.1151 | D7: 0.1151
B8: Dividend yield (q) | C8: 0.0083 | D8: 0.0083
B9: Strike price 1 | C9: 3320 | D9: 3320
B10: Strike price 2 | C10: 3300 | D10: 3300
B11: Strike price 3 | C11: 3390 | D11: 3390
A13: 2) OPTIONS PRICES
B14: European Options (XEO)
B15: Strike | C15: Call Bid | D15: Call Ask | E15: Put Bid | F15: Put Ask
B16: 3320 | C16: 141.5 | D16: 199.5 | E16: 44.1 | F16: 84.1
B17: 3300 | C17: 90.5 | D17: 130.5 | E17: 73.1 | F17: 113.1
B18: 3390 | C18: 35.2 | D18: 75.2 | E18: 101.6 | F18: 159.6
B20: American Options (OEX)
B21: Strike | C21: Call Bid | D21: Call Ask | E21: Put Bid | F21: Put Ask
B22: 3320 | C22: 137.2 | D22: 195.2 | E22: 51.6 | F22: 91.6
B23: 3300 | C23: 88.5 | D23: 128.5 | E23: 72.4 | F23: 112.4
B24: 3390 | C24: 34.8 | D24: 74.8 | E24: 101.4 | F24: 159.4
A26: 3) PUT-CALL PARITY CALCULATIONS
A27: 3.1) FORMULAS
B28: European Options (equality):
B31: American Options (inequality):
A34: 3.2) COMMON DISCOUNT FACTORS
C35: =C7*C8 -> 0.00095533
C36: 0.999045
C37: =C6*C7 -> 0.00427021
C38: 0.99573
A40: 3.3) EUROPEAN OPTIONS (XEO)
B41: i) Market Value (C-P)
B43: Strike 3320 | C43: =(C16+D16)/2 -> 170.5 | D43: =(E16+F16)/2 -> 64.1 | E43: =C43-D43 -> 106.4
B44: Strike 3300 | C44: =(C17+D17)/2 -> 110.5 | D44: =(E17+F17)/2 -> 93.1 | E44: =C44-D44 -> 17.4
B45: Strike 3390 | C45: =(C18+D18)/2 -> 55.2 | D45: =(E18+F18)/2 -> 130.6 | E45: =C45-D45 -> -75.4
B47: ii) Theoretical price (Se^(-qT)-Ke^(-rT))
B49: Strike 3320 | C49: =C5*C36 -> 3299.3062 | D49: =C9*C38 -> 3305.8236 | E49: =C49-D49 -> -6.5174493
B50: Strike 3300 | C50: =C5*C36 -> 3299.3062 | D50: =C10*C38 -> 3285.909 | E50: =C50-D50 -> 13.397151
B51: Strike 3390 | C51: =C5*C36 -> 3299.3062 | D51: =C11*C38 -> 3375.5247 | E51: =C51-D51 -> -76.218549
A53: 3.4) AMERICAN OPTIONS (OEX)
...

Sheet Black_Scholes
A1: OEX | B1: ITM | C1: ATM | D1: OTM | G1: XEO | H1: ITM | I1: ATM | J1: OTM
A2: S0 | B2: 3303 | C2: 3303 | D2: 3303 | G2: S0 | H2: 3302 | I2: 3302 | J2: 3302
A3: K | B3: 3220 | C3: 3300 | D3: 3390 | G3: K | H3: 3220 | I3: 3300 | J3: 3390
A4: r | B4: 0.0371 | C4: 0.0371 | D4: 0.0371 | G4: r | H4: 0.0371 | I4: 0.0371 | J4: 0.0371
A5: q | B5: 0.0083 | C5: 0.0083 | D5: 0.0083 | G5: q | H5: 0.0083 | I5: 0.0083 | J5: 0.0083
A6: σ | B6: 0.2773 | C6: 0.2773 | D6: 0.2773 | G6: σ | H6: 0.2773 | I6: 0.2773 | J6: 0.2773
A7: t | B7: =42/365 -> 0.11506849 | C7: =42/365 -> 0.11506849 | D7: =42/365 -> 0.11506849 | G7: t | H7: =42/365 -> 0.11506849 | I7: =42/365 -> 0.11506849 | J7: =42/365 -> 0.11506849
A9: d1 | B9: =(LN(B2/B3)+(B4-B5+(B6^2)/2)*B7)/(B6*SQRT(B7)) -> 0.35281848 | C9: =(LN(C2/C3)+(C4-C5+(C6^2)/2)*C7)/(C6*SQRT(C7)) -> 0.091923273 | D9: =(LN(D2/D3)+(D4-D5+(D6^2)/2)*D7)/(D6*SQRT(D7)) -> -0.19412841 | G9: d1 | H9: =(LN(H2/H3)+(H4-H5+(H6^2)/2)*H7)/(H6*SQRT(H7)) -> 0.34959942 | I9: =(LN(I2/I3)+(I4-I5+(I6^2)/2)*I7)/(I6*SQRT(I7)) -> 0.088704213 | J9: =(LN(J2/J3)+(J4-J5+(J6^2)/2)*J7)/(J6*SQRT(J7)) -> -0.19734747
A10: d2 | B10: =B9-B6*SQRT(B7) -> 0.25875347 | C10: =C9-C6*SQRT(C7) -> -0.0021417321 | D10: =D9-D6*SQRT(D7) -> -0.28819341 | G10: d2 | H10: =H9-H6*SQRT(H7) -> 0.25553441 | I10: =I9-I6*SQRT(I7) -> -0.0053607922 | J10: =J9-J6*SQRT(J7) -> -0.29141247
A12: N(d1) | B12: =_xlfn.NORM.S.DIST(B9,TRUE) -> 0.63788774 | C12: =_xlfn.NORM.S.DIST(C9,TRUE) -> 0.5366205 | D12: =_xlfn.NORM.S.DIST(D9,TRUE) -> 0.42303767 | G12: N(d1) | H12: =_xlfn.NORM.S.DIST(H9,TRUE) -> 0.63668033 | I12: =_xlfn.NORM.S.DIST(I9,TRUE) -> 0.53534151 | J12: =_xlfn.NORM.S.DIST(J9,TRUE) -> 0.42177782
A13: N(d2) | B13: =_xlfn.NORM.S.DIST(B10,TRUE) -> 0.60208727 | C13: =_xlfn.NORM.S.DIST(C10,TRUE) -> 0.49914557 | D13: =_xlfn.NORM.S.DIST(D10,TRUE) -> 0.38659934 | G13: N(d2) | H13: =_xlfn.NORM.S.DIST(H10,TRUE) -> 0.60084482 | I13: =_xlfn.NORM.S.DIST(I10,TRUE) -> 0.49786136 | J13: =_xlfn.NORM.S.DIST(J10,TRUE) -> 0.38536794
A15: e^-qt | B15: =EXP(-B5*B7) -> 0.99904539 | C15: =EXP(-C5*C7) -> 0.99904539 | D15: =EXP(-D5*D7) -> 0.99904539 | G15: e^-qt | H15: =EXP(-H5*H7) -> 0.99904539 | I15: =EXP(-I5*I7) -> 0.99904539 | J15: =EXP(-J5*J7) -> 0.99904539
A16: e^-rt | B16: =EXP(-B4*B7) -> 0.99574006 | C16: =EXP(-C4*C7) -> 0.99574006 | D16: =EXP(-D4*D7) -> 0.99574006 | G16: e^-rt | H16: =EXP(-H4*H7) -> 0.99574006 | I16: =EXP(-I4*I7) -> 0.99574006 | J16: =EXP(-J4*J7) -> 0.99574006
A18: Call Price | B18: =B2*B15*B12-B3*B16*B13 -> 174.4697 | C18: =C2*C15*C12-C3*C16*C13 -> 130.602 | D18: =D2*D15*D12-D3*D16*D13 -> 90.970726 | G18: Call Price | H18: =H2*H15*H12-H3*H16*H13 -> 173.83303 | I18: =I2*I15*I12-I3*I16*I13 -> 130.06653 | J18: =J2*J15*J12-J3*J16*J13 -> 90.548722
A22: Put
A23: OEX | B23: OTM | C23: ATM | D23: ITM | G23: XEO | H23: OTM | I23: ATM | J23: ITM
A24: K | B24: 3220 | C24: 3300 | D24: 3390 | G24: K | H24: 3220 | I24: 3300 | J24: 3390
A25: e^-rt | B25: =EXP(-B5*B7) -> 0.99904539 | C25: =EXP(-C5*C7) -> 0.99904539 | D25: =EXP(-D5*D7) -> 0.99904539 | G25: e^-rt | H25: =EXP(-H4*H7) -> 0.99574006 | I25: =EXP(-I4*I7) -> 0.99574006 | J25: =EXP(-J4*J7) -> 0.99574006
A26: N(d2) | B26: =_xlfn.NORM.S.DIST(B10,TRUE) -> 0.60208727 | C26: =_xlfn.NORM.S.DIST(C10,TRUE) -> 0.49914557 | D26: =_xlfn.NORM.S.DIST(D10,TRUE) -> 0.38659934 | G26: N(d2) | H26: =_xlfn.NORM.S.DIST(H10,TRUE) -> 0.60084482 | I26: =_xlfn.NORM.S.DIST(I10,TRUE) -> 0.49786136 | J26: =_xlfn.NORM.S.DIST(J10,TRUE) -> 0.38536794
A27: S0 | B27: 3303 | C27: 3303 | D27: 3303 | G27: S0 | H27: 3302 | I27: 3302 | J27: 3302
A28: E^-qt | B28: =EXP(-B5*B7) -> 0.99904539 | C28: =EXP(-C5*C7) -> 0.99904539 | D28: =EXP(-D5*D7) -> 0.99904539 | G28: E^-qt | H28: =EXP(-H5*H7) -> 0.99904539 | I28: =EXP(-I5*I7) -> 0.99904539 | J28: =EXP(-J5*J7) -> 0.99904539
A29: N(d1) | B29: =_xlfn.NORM.S.DIST(B9,TRUE) -> 0.63788774 | C29: =_xlfn.NORM.S.DIST(C9,TRUE) -> 0.5366205 | D29: =_xlfn.NORM.S.DIST(D9,TRUE) -> 0.42303767 | G29: N(d1) | H29: =_xlfn.NORM.S.DIST(H9,TRUE) -> 0.63668033 | I29: =_xlfn.NORM.S.DIST(I9,TRUE) -> 0.53534151 | J29: =_xlfn.NORM.S.DIST(J9,TRUE) -> 0.42177782
A31: Put Price | B31: =B24*B25*(1-B26)-B27*B28*(1-B29) -> 85.140823 | C31: =C24*C25*(1-C26)-C27*C28*(1-C29) -> 122.16039 | D31: =D24*D25*(1-D26)-D27*D28*(1-D29) -> 173.5558 | G31: Put Price | H31: =H24*H25*(1-H26)-H27*H28*(1-H29) -> 81.268144 | I31: =I24*I25*(1-I26)-I27*I28*(1-I29) -> 117.16085 | J31: =J24*J25*(1-J26)-J27*J28*(1-J29) -> 167.25965
A36: Comparative Table
B37: CALL | D37: PUT
B38: OEX | C38: XEO | D38: OEX | E38: XEO
A39: ITM | B39: =B18 -> 174.4697 | C39: =H18 -> 173.83303 | D39: =D31 -> 173.5558 | E39: =J31 -> 167.25965
A40: ATM | B40: =C18 -> 130.602 | C40: =I18 -> 130.06653 | D40: =C31 -> 122.16039 | E40: =I31 -> 117.16085
A41: OTM | B41: =D18 -> 90.970726 | C41: =J18 -> 90.548722 | D41: =B31 -> 85.140823 | E41: =H31 -> 81.268144

Sheet B&S_Data 
A1: oex - American
A2: Fri Apr 17 2026 | B2: OEX260417C03220000 | C2: 0 | D2: 0 | E2: 137.2 | F2: 195.2 | G2: 0 | H2: 0.2538 | I2: 0.6553 | J2: 0.0014 | K2: 0 | L2: 3220 | M2: OEX260417P03220000 | N2: 0 | O2: 0 | P2: 51.6 | Q2: 91.6 | R2: 0 | S2: 0.2544 | T2: -0.349 | U2: 0.0014 | V2: 0 | W2: ITM
A3: Fri Apr 17 2026 | B3: OEX260417C03300000 | C3: 0 | D3: 0 | E3: 88.5 | F3: 128.5 | G3: 0 | H3: 0.2246 | I3: 0.5415 | J3: 0.0017 | K3: 0 | L3: 3300 | M3: OEX260417P03300000 | N3: 0 | O3: 0 | P3: 72.4 | Q3: 112.4 | R3: 0 | S3: 0.2216 | T3: -0.4661 | U3: 0.0017 | V3: 0 | W3: ATM
A4: Fri Apr 17 2026 | B4: OEX260417C03390000 | C4: 0 | D4: 0 | E4: 34.8 | F4: 74.8 | G4: 0 | H4: 0.1914 | I4: 0.3787 | J4: 0.0018 | K4: 0 | L4: 3390 | M4: OEX260417P03390000 | N4: 0 | O4: 0 | P4: 101.4 | Q4: 159.4 | R4: 0 | S4: 0.191 | T4: -0.6356 | U4: 0.0019 | V4: 0 | W4: OTM
A6: xeo - European
A7: Fri Apr 17 2026 | B7: XEO260417C03220000 | C7: 0 | D7: 0 | E7: 141.5 | F7: 199.5 | G7: 0 | H7: 0.2631 | I7: 0.662 | J7: 0.0014 | K7: 0 | L7: 3220 | M7: XEO260417P03220000 | N7: 0 | O7: 0 | P7: 44.1 | Q7: 84.1 | R7: 0 | S7: 0.2386 | T7: -0.3372 | U7: 0.0014 | V7: 0 | W7: ITM
A8: Fri Apr 17 2026 | B8: XEO260417C03300000 | C8: 0 | D8: 0 | E8: 90.5 | F8: 130.5 | G8: 0 | H8: 0.2282 | I8: 0.5428 | J8: 0.0018 | K8: 0 | L8: 3300 | M8: XEO260417P03300000 | N8: 0 | O8: 0 | P8: 73.1 | Q8: 113.1 | R8: 0 | S8: 0.2265 | T8: -0.4564 | U8: 0.0018 | V8: 0 | W8: ATM
A9: Fri Apr 17 2026 | B9: XEO260417C03390000 | C9: 0 | D9: 0 | E9: 35.2 | F9: 75.2 | G9: 0 | H9: 0.1918 | I9: 0.3709 | J9: 0.0019 | K9: 0 | L9: 3390 | M9: XEO260417P03390000 | N9: 0 | O9: 0 | P9: 101.6 | Q9: 159.6 | R9: 0 | S9: 0.1975 | T9: -0.6283 | U9: 0.0019 | V9: 0 | W9: OTM
A11: 0.2773 | B11: σ
A12: 3303 | B12: S0 | C12: for oex
A13: 3302 | B13: S0 | C13: for xeo
A14: red boxes | B14: K | C14: strike price
A15: 0.0371 | B15: r | C15: risk free rate
A16: 0.0083 | B16: q | C16: dividend yield | E16: 0.0083
A17: =42/365 -> 0.11506849 | B17: t | C17: time to maturity | E17: 42 / 365

Sheet binomial_inputs
A1: Input Parameters
A3: Current Index (s): | C3: 3303.02
A4: Strike Price | C4: 3220
A5: Time to maturity (yrs): | C5: 0.11232877 | E5: Options Type: | G5: call
A6: risk-free rate | C6: 0.0367 | E6: Call | F6: Put
A7: Dividend yield | C7: 0.0083
A8: Volatility | C8: 0.2773 | E8: Euro index: | G8: 3302.46
A9: Number of steps(n) | C9: 3 | E9: Amer index: | G9: 3303.02
A11: Binomial Parameters
A13: time per step | C13: =C5/C9 -> 0.037442922
A14: up factor | C14: =EXP(C8*SQRT(C13)) -> 1.0551237
A15: down factor | C15: =1/C14 -> 0.94775615
A16: growth factor | C16: =EXP((C6-C7)*C13) -> 1.0010639
A17: risk- neutral prob | C17: =(C16-C15)/(C14-C15) -> 0.49649808
A18: 1-p | C18: =1-C17 -> 0.50350192
A19: Discount factor per step | C19: =EXP(-C6*C13) -> 0.99862679

Sheet binomial_Base_model
A1: Index Price tree
A2: steps:3
A4: Time = 0 | C4: Time = 1 | E4: Time =2 | G4: Time = 3
A6: S00 | C6: S11: | E6: S22 | G6: S33
A7: =binomial_inputs!C$3 -> 3303.02 | C7: =A7*binomial_inputs!$C$14 -> 3485.0948 | E7: =A7*binomial_inputs!$C$14^2 -> 3677.2061 | G7: =A7*binomial_inputs!$C$14^3 -> 3879.9074
C9: S10: | E9: S21 | G9: S32
C10: =A7*binomial_inputs!$C$15 -> 3130.4575 | E10: =A7*binomial_inputs!$C$14*binomial_inputs!$C$15 -> 3303.02 | G10: =A7*binomial_inputs!$C$14^2*binomial_inputs!$C$15 -> 3485.0948
E12: S20 | G12: S31
E13: =A7*binomial_inputs!$C$15^2 -> 2966.9104 | G13: =A7*binomial_inputs!$C$14*binomial_inputs!$C$15^2 -> 3130.4575
G15: S30
G16: =A7*binomial_inputs!$C$15^3 -> 2811.9076

Sheet Binomial_Euro_opt
A1: European option pricing - 3-step binomial
A3: Options Type: | C3: =binomial_inputs!$G$5 -> call
A4: Strike price (K): | C4: =binomial_inputs!$C$4 -> 3220
A6: Index Tree
A8: Time 0 | C8: Time 1 | E8: Time 2 | G8: Time 3 | H8: Payoff at time 3
A10: S00: | C10: S11: | E10: S22: | G10: S33: | H10: Payoff 30
A11: =binomial_Base_model!$A$7 -> 3303.02 | C11: =binomial_Base_model!$C$7 -> 3485.0948 | E11: =binomial_Base_model!$E$7 -> 3677.2061 | G11: =binomial_Base_model!$G$7 -> 3879.9074 | H11: =IF($C$3="Call", MAX(G11-$C$4,0), MAX($C$4-G11,0)) -> 659.90744
C13: S10: | E13: S21: | G13: S32: | H13: Payoff 31
C14: =binomial_Base_model!$C$10 -> 3130.4575 | E14: =binomial_Base_model!$E$10 -> 3303.02 | G14: =binomial_Base_model!$G$10 -> 3485.0948 | H14: =IF($C$3="Call", MAX(G14-$C$4,0), MAX($C$4-G14,0)) -> 265.09476
E16: S20: | G16: S31: | H16: Payoff 32
E17: =binomial_Base_model!$E$13 -> 2966.9104 | G17: =binomial_Base_model!$G$13 -> 3130.4575 | H17: =IF($C$3="Call", MAX(G17-$C$4,0), MAX($C$4-G17,0)) -> 0
G19: S30: | H19: Payoff 33
G20: =binomial_Base_model!$G$16 -> 2811.9076 | H20: =IF($C$3="Call", MAX(G20-$C$4,0), MAX($C$4-G20,0)) -> 0
A22: Backwards Induction:
A24: Step 3 - Step 2:
A26: Time 2 Values:
A27: V22: | B27: =binomial_inputs!$C$19*(binomial_inputs!$C$17*H11 + binomial_inputs!$C$18*H14) -> 460.48528
A28: V21: | B28: =binomial_inputs!$C$19*(binomial_inputs!$C$17*H14+binomial_inputs!$C$18*H17) -> 131.4383
A29: V20 | B29: =binomial_inputs!$C$19*(binomial_inputs!$C$17*H17+binomial_inputs!$C$18*H20) -> 0
A31: Step 2 - Step 1:
A33: Time 1 Values:
A34: V11: | B34: =binomial_inputs!$C$19*(binomial_inputs!$C$17*B27+binomial_inputs!$C$18*B28) -> 294.40465
A35: V10: | B35: =binomial_inputs!$C$19*(binomial_inputs!$C$17*B28 + binomial_inputs!$C$18*B29) -> 65.169246
A37: Step 1 to Step 0:
A39: Time 0 Value:
A40: V00: | B40: =binomial_inputs!$C$19*(binomial_inputs!$C$17*B34 + binomial_inputs!$C$18*B35) -> 178.7384
A42: Euro Opt Price: | C42: =B40 -> 178.7384

Sheet binomial_Amer_opt
A1: American Options - 3- step binomial
A3: Options Type: | C3: =binomial_inputs!$G$5 -> call
A4: Strike price (K): | C4: =binomial_inputs!$C$4 -> 3220
A6: Index Tree
A8: Time 0 | C8: Time 1 | E8: Time 2 | G8: Time 3 | H8: Payoff at time 3
A10: S00: | C10: S11: | E10: S22 | G10: S33: | H10: Payoff 30
A11: =binomial_Base_model!$A$7 -> 3303.02 | C11: =binomial_Base_model!$C$7 -> 3485.0948 | E11: =binomial_Base_model!$E$7 -> 3677.2061 | G11: =binomial_Base_model!$G$7 -> 3879.9074 | H11: =IF($C$3="Call", MAX(G11-$C$4,0), MAX($C$4-G11,0)) -> 659.90744
C13: S10: | E13: S21: | G13: S32: | H13: Payoff 31
C14: =binomial_Base_model!$C$10 -> 3130.4575 | E14: =binomial_Base_model!$E$10 -> 3303.02 | G14: =binomial_Base_model!$G$10 -> 3485.0948 | H14: =IF($C$3="Call", MAX(G14-$C$4,0), MAX($C$4-G14,0)) -> 265.09476
E16: S20: | G16: S31: | H16: Payoff 32
E17: =binomial_Base_model!$E$13 -> 2966.9104 | G17: =binomial_Base_model!$G$13 -> 3130.4575 | H17: =IF($C$3="Call", MAX(G17-$C$4,0), MAX($C$4-G17,0)) -> 0
G19: S30: | H19: Payoff 33
G20: =binomial_Base_model!$G$16 -> 2811.9076 | H20: =IF($C$3="Call", MAX(G20-$C$4,0), MAX($C$4-G20,0)) -> 0
A22: Backwards Induction With Early Exrcise Check
A24: Step 3 to Step 2:
A26: At Time 2 - Node S22:
A27: Hold22: | B27: =binomial_inputs!$C$19*(binomial_inputs!$C$17*H11 + binomial_inputs!$C$18*H14) -> 460.48528
A28: Exercise22: | B28: =IF($C$3="Call", MAX(E11-$C$4,0), MAX($C$4-E11,0)) -> 457.20615
A29: V22: | B29: =MAX(B27, B28) -> 460.48528
A31: At Time 2 - Node S21:
A32: Hold21: | B32: =binomial_inputs!$C$19*(binomial_inputs!$C$17*H14 + binomial_inputs!$C$18*H17) -> 131.4383
A33: Exercise21: | B33: =IF($C$3="Call", MAX(E14-$C$4,0), MAX($C$4-E14,0)) -> 83.02
A34: V21: | B34: =MAX(B32, B33) -> 131.4383
A36: At Time 2 - Node S22:
A37: Hold20: | B37: =binomial_inputs!$C$19*(binomial_inputs!$C$17*H17 + binomial_inputs!$C$18*H20) -> 0
A38: Exercise20: | B38: =IF($C$3="Call", MAX(E17-$C$4,0), MAX($C$4-E17,0)) -> 0
A39: V20: | B39: =MAX(B37, B38) -> 0
A41: Step 2 to Step 1:
A43: At Time 1 - Node S11
A44: Hold11: | B44: =binomial_inputs!$C$19*(binomial_inputs!$C$17*B29 + binomial_inputs!$C$18*B34) -> 294.40465
A45: Exercise11: | B45: =IF($C$3="Call", MAX(C11-$C$4,0), MAX($C$4-C11,0)) -> 265.09476
A46: V11: | B46: =MAX(B44, B45) -> 294.40465
A48: At Time 1 - Node S10
A49: Hold10: | B49: =binomial_inputs!$C$19*(binomial_inputs!$C$17*B34 + binomial_inputs!$C$18*B39) -> 65.169246
A50: Exercise10: | B50: =IF($C$3="Call", MAX(C14-$C$4,0), MAX($C$4-C14,0)) -> 0
A51: V10: | B51: =MAX(B49, B50) -> 65.169246
A53: Step 1 to Step 0:
A55: At Time 0 - Node S00
A56: Hold00: | B56: =binomial_inputs!$C$19*(binomial_inputs!$C$17*B46 + binomial_inputs!$C$18*B51) -> 178.7384
A57: Exercise00: | B57: =IF($C$3="Call", MAX(A11-$C$4,0), MAX($C$4-A11,0)) -> 83.02
...

Sheet Binomial_Results
A1: Binomial Model Prices - 3 step tree
A3: American Option (OEX):
A4: Category | B4: Type | C4: Strike | D4: Index | E4: T(years) | F4: Caluculated Price
A5: ITM | B5: Call | C5: 3220 | D5: 3303.02 | E5: =binomial_inputs!$C$5 -> 0.11232877 | F5: 178.7384
A6: OTM | B6: Put | C6: 3220 | D6: 3303.02 | E6: =binomial_inputs!$C$5 -> 0.11232877 | F6: 86.43428
A7: ATM | B7: Call | C7: 3300 | D7: 3303.02 | E7: =binomial_inputs!$C$5 -> 0.11232877 | F7: 139.3215
A8: ATM | B8: Put | C8: 3300 | D8: 3303.02 | E8: =binomial_inputs!$C$5 -> 0.11232877 | F8: 126.716
A9: OTM | B9: Call | C9: 3390 | D9: 3303.02 | E9: =binomial_inputs!$C$5 -> 0.11232877 | F9: 94.97739
A10: ITM | B10: Put | C10: 3390 | D10: 3303.02 | E10: =binomial_inputs!$C$5 -> 0.11232877 | F10: 172.0329
A12: European Options (XEO):
A13: Category | B13: Type | C13: Strike | D13: Index | E13: T(years) | F13: Calculated Price
A14: ITM | B14: Call | C14: 3220 | D14: 3302.46 | E14: =binomial_inputs!$C$5 -> 0.11232877 | F14: 178.4391
A15: OTM | B15: Put | C15: 3220 | D15: 3302.46 | E15: =binomial_inputs!$C$5 -> 0.11232877 | F15: 85.80964
A16: ATM | B16: Call | C16: 3300 | D16: 3302.46 | E16: =binomial_inputs!$C$5 -> 0.11232877 | F16: 139.0222
A17: ATM | B17: Put | C17: 3300 | D17: 3302.46 | E17: =binomial_inputs!$C$5 -> 0.11232877 | F17: 126.9762
A18: OTM | B18: Call | C18: 3390 | D18: 3302.46 | E18: =binomial_inputs!$C$5 -> 0.11232877 | F18: 94.67811
A19: ITM | B19: Put | C19: 3390 | D19: 3302.46 | E19: =binomial_inputs!$C$5 -> 0.11232877 | F19: 171.3493

Sheet Final_results
B3: Calls | H3: Puts
B4: American | E4: European | H4: American | K4: European
B5: B&S | C5: Actual | D5: Binomial | E5: B&S | F5: Actual | G5: Binomial | H5: B&S | I5: Actual | J5: Binomial | K5: B&S | L5: Actual | M5: Binomial
A6: ITM | B6: 174.4697 | C6: 179.6 | D6: 178.7384 | E6: 173.8330 | F6: 178.1 | G6: 178.4391 | H6: 85.1408 | I6: 137.9 | J6: 172.0329 | K6: 167.2596 | L6: 136.1 | M6: 171.3493
A7: ATM | B7: 130.6020 | C7: 92.6 | D7: 139.3215 | E7: 130.0665 | F7: 110.8 | G7: 139.0222 | H7: 122.1604 | I7: 113.4 | J7: 126.716 | K7: 117.1609 | L7: 975 | M7: 126.9762
A8: OTM | B8: 90.9707 | C8: 58 | D8: 94.9773 | E8: 90.5487 | F8: 58.5 | G8: 94.6781 | H8: 173.5558 | I8: 77.3 | J8: 86.4342 | K8: 81.2681 | L8: 76.8 | M8: 85.8096
M14: `
